HOST lewis.lbl.gov
only_i 152
only_code None
force_amber_prep True
dry_run False
... 152 3ku8
/net/chevy/raid1/nigel/amber/hi_lo
/net/chevy/raid1/nigel/amber/hi_lo/ku/3ku8
3ku8.pdb 4phenix_3ku8.pdb
3ku8.pdb 4phenix_3ku8.pdb
local_archive None
archive PDB None
Traceback (most recent call last):
  File "/net/cci-filer2/raid1/xp/phenix/phenix-svn/build/../modules/cctbx_project/mmtbx/command_line/fetch_pdb.py", line 199, in <module>
    run2(sys.argv[1:])
  File "/net/cci-filer2/raid1/xp/phenix/phenix-svn/build/../modules/cctbx_project/mmtbx/command_line/fetch_pdb.py", line 155, in run2
    files.append(get_pdb(id, data_type_, mirror, log, format=data_format))
  File "/net/cci-filer2/raid1/xp/phenix/phenix-svn/modules/cctbx_project/iotbx/pdb/fetch.py", line 213, in get_pdb
    data = fetch(id, data_type, mirror=mirror, format=format, log=log)
  File "/net/cci-filer2/raid1/xp/phenix/phenix-svn/modules/cctbx_project/iotbx/pdb/fetch.py", line 173, in fetch
    data = libtbx.utils.urlopen(url)
  File "/net/cci-filer2/raid1/xp/phenix/phenix-svn/modules/cctbx_project/libtbx/utils.py", line 2069, in urlopen
    return urllib2.urlopen(*args, **kwds)
  File "/net/cci-filer2/raid1/xp/phenix/phenix-svn/base/lib/python2.7/urllib2.py", line 127, in urlopen
    return _opener.open(url, data, timeout)
  File "/net/cci-filer2/raid1/xp/phenix/phenix-svn/base/lib/python2.7/urllib2.py", line 404, in open
    response = self._open(req, data)
  File "/net/cci-filer2/raid1/xp/phenix/phenix-svn/base/lib/python2.7/urllib2.py", line 422, in _open
    '_open', req)
  File "/net/cci-filer2/raid1/xp/phenix/phenix-svn/base/lib/python2.7/urllib2.py", line 382, in _call_chain
    result = func(*args)
  File "/net/cci-filer2/raid1/xp/phenix/phenix-svn/base/lib/python2.7/urllib2.py", line 1214, in http_open
    return self.do_open(httplib.HTTPConnection, req)
  File "/net/cci-filer2/raid1/xp/phenix/phenix-svn/base/lib/python2.7/urllib2.py", line 1184, in do_open
    raise URLError(err)
urllib2.URLError: <urlopen error [Errno 110] Connection timed out>
Traceback (most recent call last):
  File "run_tests_local.py", line 323, in <module>
    run(*tuple(args))
  File "run_tests_local.py", line 302, in run
    mtz_file = get_mtz_filename(code)
  File "/net/chevy/raid1/nigel/amber/hi_lo/run_utils.py", line 421, in get_mtz_filename
    assert 0
AssertionError
